<?xml version="1.0"?>
<robot name="wx250s" xmlns:xacro="http://ros.org/wiki/xacro">

  <xacro:arg name="robot_name" default = "wx250s"/>
  <xacro:arg name="base_link_frame" default="base_link"/>
  <xacro:arg name="show_gripper_bar" default="true"/>
  <xacro:arg name="show_gripper_fingers" default="true"/>

  <xacro:property name="pi_offset" value="0.00001"/>


  <material name="interbotix_black">
    <texture filename="package://ourbeloved/mesh/interbotix_black.png"/>
  </material>

  <link name="$(arg robot_name)/$(arg base_link_frame)">
    <visual>
      <origin rpy="0 0 ${pi/2}" xyz="0 0 0"/>
      <geometry>
        <mesh filename="package://ourbeloved/mesh/wx250s_1_base.stl" scale="0.001 0.001 0.001"/>
      </geometry>
      <material name="interbotix_black"/>
    </visual>
  </link>

  <joint name="waist" type="revolute">
    <axis xyz="0 0 1"/>
    <limit effort="10" lower="${-pi + pi_offset}" upper="${pi - pi_offset}" velocity="${pi}"/>
    <origin rpy="0 0 0" xyz="0 0 0.072"/>
    <parent link="$(arg robot_name)/$(arg base_link_frame)"/>
    <child link="$(arg robot_name)/shoulder_link"/>
  </joint>

  <link name="$(arg robot_name)/shoulder_link">
    <visual>
      <origin rpy="0 0 ${pi/2}" xyz="0 0 -0.003"/>
      <geometry>
        <mesh filename="package://ourbeloved/mesh/wx250s_2_shoulder.stl" scale="0.001 0.001 0.001"/>
      </geometry>
      <material name="interbotix_black"/>
    </visual>
  </link>

  <joint name="shoulder" type="revolute">
    <axis xyz="0 -1 0"/>
    <limit effort="20" lower="${radians(-108)}" upper="${radians(114)}" velocity="${pi}"/>
    <origin rpy="0 0 0" xyz="0 0 0.03865"/>
    <parent link="$(arg robot_name)/shoulder_link"/>
    <child link="$(arg robot_name)/upper_arm_link"/>
  </joint>

  <link name="$(arg robot_name)/upper_arm_link">
    <visual>
      <origin rpy="0 0 ${pi/2}" xyz="0 0 0"/>
      <geometry>
        <mesh filename="package://ourbeloved/mesh/wx250s_3_upper_arm.stl" scale="0.001 0.001 0.001"/>
      </geometry>
      <material name="interbotix_black"/>
    </visual>
  </link>

  <joint name="elbow" type="revolute">
    <axis xyz="0 -1 0"/>
    <limit effort="15" lower="${radians(-123)}" upper="${radians(92)}" velocity="${pi}"/>
    <origin rpy="0 0 0" xyz="0.04975 0 0.25"/>
    <parent link="$(arg robot_name)/upper_arm_link"/>
    <child link="$(arg robot_name)/upper_forearm_link"/>
  </joint>

  <link name="$(arg robot_name)/upper_forearm_link">
    <visual>
      <origin rpy="0 0 0" xyz="0 0 0"/>
      <geometry>
        <mesh filename="package://ourbeloved/mesh/wx250s_4_upper_forearm.stl" scale="0.001 0.001 0.001"/>
      </geometry>
      <material name="interbotix_black"/>
    </visual>
  </link>

  <joint name="forearm_roll" type="revolute">
    <axis xyz="1 0 0"/>
    <limit effort="2" lower="${-pi + pi_offset}" upper="${pi - pi_offset}" velocity="${pi}"/>
    <origin rpy="0 0 0" xyz="0.175 0 0"/>
    <parent link="$(arg robot_name)/upper_forearm_link"/>
    <child link="$(arg robot_name)/lower_forearm_link"/>
  </joint>

  <link name="$(arg robot_name)/lower_forearm_link">
    <visual>
      <origin rpy="${pi} 0 0" xyz="0 0 0"/>
      <geometry>
        <mesh filename="package://ourbeloved/mesh/wx250s_5_lower_forearm.stl" scale="0.001 0.001 0.001"/>
      </geometry>
      <material name="interbotix_black"/>
    </visual>
  </link>

  <joint name="wrist_angle" type="revolute">
    <axis xyz="0 -1 0"/>
    <limit effort="5" lower="${radians(-100)}" upper="${radians(123)}" velocity="${pi}"/>
    <origin rpy="0 0 0" xyz="0.075 0 0"/>
    <parent link="$(arg robot_name)/lower_forearm_link"/>
    <child link="$(arg robot_name)/wrist_link"/>
  </joint>

  <link name="$(arg robot_name)/wrist_link">
    <visual>
      <origin rpy="0 0 ${pi/2}" xyz="0 0 0"/>
      <geometry>
        <mesh filename="package://ourbeloved/mesh/wx250s_6_wrist.stl" scale="0.001 0.001 0.001"/>
      </geometry>
      <material name="interbotix_black"/>
    </visual>
  </link>

  <joint name="wrist_rotate" type="revolute">
    <axis xyz="1 0 0"/>
    <limit effort="1" lower="${-pi + pi_offset}" upper="${pi - pi_offset}" velocity="${pi}"/>
    <origin rpy="0 0 0" xyz="0.065 0 0"/>
    <parent link="$(arg robot_name)/wrist_link"/>
    <child link="$(arg robot_name)/gripper_link"/>
  </joint>

  <link name="$(arg robot_name)/gripper_link">
    <visual>
      <origin rpy="0 0 ${pi/2}" xyz="-0.02 0 0"/>
      <geometry>
        <mesh filename="package://ourbeloved/mesh/wx250s_7_gripper.stl" scale="0.001 0.001 0.001"/>
      </geometry>
      <material name="interbotix_black"/>
    </visual>
  </link>

  <joint name="ee_arm" type="fixed">
    <axis xyz="1 0 0"/>
    <origin rpy="0 0 0" xyz="0.043 0 0"/>
    <parent link="$(arg robot_name)/gripper_link"/>
    <child link="$(arg robot_name)/ee_arm_link"/>
  </joint>

  <link name="$(arg robot_name)/ee_arm_link">
  </link>

  <joint name="gripper" type="continuous">
    <axis xyz="1 0 0"/>
    <limit effort="1" velocity="${pi}"/>
    <origin rpy="0 0 0" xyz="0.0055 0 0"/>
    <parent link="$(arg robot_name)/ee_arm_link"/>
    <child link="$(arg robot_name)/gripper_prop_link"/>
  </joint>

  <link name="$(arg robot_name)/gripper_prop_link">
    <visual>
      <origin rpy="0 0 ${pi/2}" xyz="-0.0685 0 0"/>
      <geometry>
        <mesh filename="package://ourbeloved/mesh/wx250s_8_gripper_prop.stl" scale="0.001 0.001 0.001"/>
      </geometry>
      <material name="interbotix_black"/>
    </visual>
  </link>

  <joint name="gripper_bar" type="fixed">
    <axis xyz="1 0 0"/>
    <origin rpy="0 0 0" xyz="0 0 0"/>
    <parent link="$(arg robot_name)/ee_arm_link"/>
    <child link="$(arg robot_name)/gripper_bar_link"/>
  </joint>

  <link name="$(arg robot_name)/gripper_bar_link">
    <visual>
      <origin rpy="0 0 ${pi/2}" xyz="-0.063 0 0"/>
      <geometry>
        <mesh filename="package://ourbeloved/mesh/wx250s_9_gripper_bar.stl" scale="0.001 0.001 0.001"/>
      </geometry>
      <material name="interbotix_black"/>
    </visual>
  </link>

  <joint name="ee_bar" type="fixed">
    <axis xyz="1 0 0"/>
    <origin rpy="0 0 0" xyz="0.023 0 0"/>
    <parent link="$(arg robot_name)/gripper_bar_link"/>
    <child link="$(arg robot_name)/fingers_link"/>
  </joint>

  <link name="$(arg robot_name)/fingers_link">
  </link>

  <joint name="left_finger" type="prismatic">
    <axis xyz="0 1 0"/>
    <limit effort="5" lower="0.015" upper="0.037" velocity="1"/>
    <origin rpy="0 0 0" xyz="0 0 0"/>
    <parent link="$(arg robot_name)/fingers_link"/>
    <child link="$(arg robot_name)/left_finger_link"/>
  </joint>

  <link name="$(arg robot_name)/left_finger_link">
    <visual>
      <origin rpy="${pi} ${pi} 0" xyz="0 0.005 0"/>
      <geometry>
        <mesh filename="package://ourbeloved/mesh/wx250s_10_gripper_finger.stl" scale="0.001 0.001 0.001"/>
      </geometry>
      <material name="interbotix_black"/>
    </visual>
  </link>

  <joint name="right_finger" type="prismatic">
    <axis xyz="0 1 0"/>
    <limit effort="5" lower="-0.037" upper="-0.015" velocity="1"/>
    <origin rpy="0 0 0" xyz="0 0 0"/>
    <parent link="$(arg robot_name)/fingers_link"/>
    <child link="$(arg robot_name)/right_finger_link"/>
    <mimic joint="left_finger" multiplier="-1" offset="0"/>
  </joint>

  <link name="$(arg robot_name)/right_finger_link">
    <visual>
      <origin rpy="0 ${pi} 0" xyz="0 -0.005 0"/>
      <geometry>
        <mesh filename="package://ourbeloved/mesh/wx250s_10_gripper_finger.stl" scale="0.001 0.001 0.001"/>
      </geometry>
      <material name="interbotix_black"/>
    </visual>
  </link>

  <joint name="ee_gripper" type="fixed">
    <axis xyz="1 0 0"/>
    <origin rpy="0 0 0" xyz="0.027575 0 0"/>
    <parent link="$(arg robot_name)/fingers_link"/>
    <child link="$(arg robot_name)/ee_gripper_link"/>
  </joint>

  <link name="$(arg robot_name)/ee_gripper_link">
  </link>

</robot>
